#exception.py

class MergeError(Exception):
    ...
    pass